Workbook
Name InputAmounts: SharedData!$E$6:$E$25
Name InputCashDates: SharedData!$M$6:$M$15
Name InputCashFlows: SharedData!$L$6:$L$15
Name InputCategories: SharedData!$C$6:$C$25
Name InputDates: SharedData!$D$6:$D$25
Name InputLabels: SharedData!$B$6:$B$25
Name InputNumbers: SharedData!$A$6:$A$25
Name InputWeights: SharedData!$F$6:$F$25

Sheet Overview
A1: CellRune Excel Oracle — deterministic function atlas
A2: Excel-authored cache oracle covering the plan's 10 sheets, CSE/dynamic arrays, reference semantics, structured/3-D references, and a Microsoft function catalog broader than CellRune.
A4: Active oracle formulas | B4: =SUM(B8:B17) -> 672 | D4: Catalogued functions | E4: 522 | G4: CellRune catalog | H4: 279 | J4: Breadth ratio | K4: =E4/H4 -> 1.8709677
A5: Deterministic active functions | B5: 494 | D5: Explicit exclusions | E5: 28 | G5: Date system | H5: 1900 | J5: Saved by | K5: Microsoft Excel for Mac
A7: Oracle sheet | B7: Active formulas | C7: Primary cases | D7: All formulas incl. sentinels | E7: Coverage focus
A8: Arithmetic | B8: =Arithmetic!$S$4 -> 162 | C8: =Arithmetic!$S$3 -> 162 | D8: 200 | E8: Near-zero cancellation, 15-digit residue, math/trig/engineering
A9: Aggregates | B9: =Aggregates!$S$4 -> 174 | C9: =Aggregates!$S$3 -> 174 | D9: 214 | E9: Aggregate, database, statistical, mixed-type and empty-range behavior
A10: ArraysCSE | B10: =ArraysCSE!$S$4 -> 16 | C10: =ArraysCSE!$S$3 -> 16 | D10: 23 | E10: Legacy array formulas, broadcasting, padding, mixed array literals
A11: ArraysDynamic | B11: =ArraysDynamic!$S$4 -> 65 | C11: =ArraysDynamic!$S$3 -> 65 | D11: 83 | E11: Spill arrays, Lambda helpers, shape transforms and blockers
A12: Intersection | B12: =Intersection!$S$4 -> 11 | C12: =Intersection!$S$3 -> 11 | D12: 17 | E12: Implicit intersection, union/intersection/range, whole row/column and 3-D
A13: Financial | B13: =Financial!$S$4 -> 61 | C13: =Financial!$S$3 -> 61 | D13: 78 | E13: Cash-flow solvers, securities, convergence and #NUM! boundaries
A14: Lookup | B14: =Lookup!$S$4 -> 34 | C14: =Lookup!$S$3 -> 34 | D14: 45 | E14: Legacy and modern lookup, approximate match, structured references
A15: TextDate | B15: =TextDate!$S$4 -> 86 | C15: =TextDate!$S$3 -> 86 | D15: 108 | E15: Text, regex, date/time, 1900 leap-year and locale-sensitive formatting
A16: Errors | B16: =Errors!$S$4 -> 43 | C16: =Errors!$S$3 -> 45 | D16: 56 | E16: Error propagation, catchers, error arguments and iterative circular cells
A17: Unsupported | B17: =Unsupported!$S$4 -> 20 | C17: =Unsupported!$S$3 -> 49 | D17: 26 | E17: LET/LAMBDA, 3-D, structured refs, external/volatile exclusions
A20: Oracle rules | B20: No current time or random functions; all input ranges are visible; every cross-sheet reference is quoted; Excel owns the saved cache.
A21: Source catalog | B21: https://support.microsoft.com/en-US/Excel/excel-functions-alphabetical
A23: Recalculation protocol | B23: Open in Microsoft Excel → Calculate Now / F9 → save as .xlsx → verify formula cells contain cached <v> values.
A25: Sentinel chain | B25: =SUM(Arithmetic!$P$5,Aggregates!$P$5,ArraysCSE!$P$5,ArraysDynamic!$P$5,Intersection!$P$5,Financial!$P$5,Lookup!$P$5,TextDate!$P$5,Errors!$P$5,Unsupported!$P$5) -> 1900.6005

Sheet SharedData
A1: SharedData — deterministic workbook inputs | P1: Spill anchor | R1: Blocked spill | S1: T/U/V below are header-less numeric columns for whole-column array cases (T,U = 20 rows; V = 12).
A2: Every oracle sheet references these typed inputs. No mock/random/current-time data is used. | O2: =O3+1 | P2: {=_xlfn.SEQUENCE(5)} -> 1 | R2: {=_xlfn.SEQUENCE(4)} -> #VALUE!
O3: =O2+1 | P3: 2
P4: 3 | R4: blocker
A5: Number | B5: Key | C5: Category | D5: Date | E5: Amount | F5: Quantity | G5: Flag | H5: Mixed | I5: X | J5: Y = 2X+3 | K5: Probability | L5: Cash flow | M5: Cash date | N5: Complex text | P5: 4
A6: 0.1 | B6: K001 | C6: A | D6: 43831 | E6: 10 | F6: 1 | G6: TRUE | I6: 1 | J6: =I6*2+3 -> 5 | K6: 0.05 | L6: -1000 | M6: 43831 | N6: 1+1i | P6: 5 | T6: 1 | U6: 2 | V6: 1
A7: 0.2 | B7: K002 | C7: B | D7: 43862 | E7: 20 | F7: 2 | G7: FALSE | H7: text | I7: 2 | J7: =I7*2+3 -> 7 | K7: 0.05 | L7: 180 | M7: 44012 | N7: 2+2i | T7: 2 | U7: 4 | V7: 2
A8: -0.3 | B8: K003 | C8: C | D8: 43893 | E8: 30 | F8: 3 | G8: TRUE | H8: TRUE | I8: 3 | J8: =I8*2+3 -> 9 | K8: 0.05 | L8: 220 | M8: 44193 | N8: 3+3i | T8: 3 | U8: 6 | V8: 3
A9: 1 | B9: K004 | C9: A | D9: 43924 | E9: 40 | F9: 4 | G9: FALSE | H9: FALSE | I9: 4 | J9: =I9*2+3 -> 11 | K9: 0.05 | L9: 260 | M9: 44374 | N9: 4+4i | T9: 4 | U9: 8 | V9: 4
A10: 2 | B10: K005 | C10: B | D10: 43955 | E10: 50 | F10: 5 | G10: TRUE | H10: 0 | I10: 5 | J10: =I10*2+3 -> 13 | K10: 0.05 | L10: 300 | M10: 44555 | N10: 5+5i | T10: 5 | U10: 10 | V10: 5
A11: 3 | B11: K006 | C11: C | D11: 43986 | E11: 60 | F11: 6 | G11: FALSE | H11: 0 | I11: 6 | J11: =I11*2+3 -> 15 | K11: 0.05 | L11: 340 | M11: 44736 | N11: 6+1i | T11: 6 | U11: 12 | V11: 6
A12: 4 | B12: K007 | C12: A | D12: 44017 | E12: 70 | F12: 7 | G12: TRUE | I12: 7 | J12: =I12*2+3 -> 17 | K12: 0.05 | L12: 380 | M12: 44917 | N12: 7+2i | T12: 7 | U12: 14 | V12: 7
A13: 5 | B13: K008 | C13: B | D13: 44048 | E13: 80 | F13: 1 | G13: FALSE | H13: CellRune | I13: 8 | J13: =I13*2+3 -> 19 | K13: 0.05 | L13: -50 | M13: 45098 | N13: 8+3i | T13: 8 | U13: 16 | V13: 8
A14: 10 | B14: K009 | C14: C | D14: 44079 | E14: 90 | F14: 2 | G14: TRUE | H14: TRUE | I14: 9 | J14: =I14*2+3 -> 21 | K14: 0.05 | L14: 420 | M14: 45279 | N14: 9+4i | T14: 9 | U14: 18 | V14: 9
A15: -10 | B15: K010 | C15: A | D15: 44110 | E15: 100 | F15: 3 | G15: FALSE | H15: -1 | I15: 10 | J15: =I15*2+3 -> 23 | K15: 0.05 | L15: 500 | M15: 45460 | N15: 10+5i | T15: 10 | U15: 20 | V15: 10
A16: 25 | B16: K011 | C16: B | D16: 44141 | E16: 110 | F16: 4 | G16: TRUE | I16: 11 | J16: =I16*2+3 -> 25 | K16: 0.05 | N16: 11+1i | T16: 11 | U16: 22 | V16: 11
A17: 100 | B17: K012 | C17: C | D17: 44172 | E17: 120 | F17: 5 | G17: FALSE | H17: text | I17: 12 | J17: =I17*2+3 -> 27 | K17: 0.05 | N17: 12+2i | T17: 12 | U17: 24 | V17: 12
A18: 0 | B18: K013 | C18: A | D18: 44203 | E18: 130 | F18: 6 | G18: TRUE | H18: TRUE | I18: 13 | J18: =I18*2+3 -> 29 | K18: 0.05 | N18: 13+3i | T18: 13 | U18: 26
A19: 1.5 | B19: K014 | C19: B | D19: 44234 | E19: 140 | F19: 7 | G19: FALSE | H19: FALSE | I19: 14 | J19: =I19*2+3 -> 31 | K19: 0.05 | N19: 14+4i | T19: 14 | U19: 28
A20: 2.5 | B20: K015 | C20: C | D20: 44265 | E20: 150 | F20: 1 | G20: TRUE | H20: 0 | I20: 15 | J20: =I20*2+3 -> 33 | K20: 0.05 | N20: 15+5i | T20: 15 | U20: 30
A21: 3.5 | B21: K016 | C21: A | D21: 44296 | E21: 160 | F21: 2 | G21: FALSE | H21: 0 | I21: 16 | J21: =I21*2+3 -> 35 | K21: 0.05 | N21: 16+1i | T21: 16 | U21: 32
A22: 4.5 | B22: K017 | C22: B | D22: 44327 | E22: 170 | F22: 3 | G22: TRUE | I22: 17 | J22: =I22*2+3 -> 37 | K22: 0.05 | N22: 17+2i | T22: 17 | U22: 34
A23: 5.5 | B23: K018 | C23: C | D23: 44358 | E23: 180 | F23: 4 | G23: FALSE | H23: CellRune | I23: 18 | J23: =I23*2+3 -> 39 | K23: 0.05 | N23: 18+3i | T23: 18 | U23: 36
A24: 0.05 | B24: K019 | C24: A | D24: 44389 | E24: 190 | F24: 5 | G24: TRUE | H24: TRUE | I24: 19 | J24: =I24*2+3 -> 41 | K24: 0.05 | N24: 19+4i | T24: 19 | U24: 38
A25: 0.1 | B25: K020 | C25: B | D25: 44420 | E25: 200 | F25: 6 | G25: FALSE | H25: -1 | I25: 20 | J25: =I25*2+3 -> 43 | K25: 0.05 | N25: 20+5i | T25: 20 | U25: 40
A30: Key | B30: Category | C30: Date | D30: Amount | E30: Quantity | F30: Flag | H30: Category | I30: Amount
A31: K001 | B31: A | C31: 43831 | D31: 10 | E31: 1 | F31: TRUE | H31: A | I31: >50
A32: K002 | B32: B | C32: 43862 | D32: 20 | E32: 2 | F32: FALSE | H32: B | I32: <=120
A33: K003 | B33: C | C33: 43893 | D33: 30 | E33: 3 | F33: TRUE
A34: K004 | B34: A | C34: 43924 | D34: 40 | E34: 4 | F34: FALSE
A35: K005 | B35: B | C35: 43955 | D35: 50 | E35: 5 | F35: TRUE
A36: K006 | B36: C | C36: 43986 | D36: 60 | E36: 6 | F36: FALSE
A37: K007 | B37: A | C37: 44017 | D37: 70 | E37: 7 | F37: TRUE
A38: K008 | B38: B | C38: 44048 | D38: 80 | E38: 1 | F38: FALSE
A39: K009 | B39: C | C39: 44079 | D39: 90 | E39: 2 | F39: TRUE
A40: K010 | B40: A | C40: 44110 | D40: 100 | E40: 3 | F40: FALSE
A41: K011 | B41: B | C41: 44141 | D41: 110 | E41: 4 | F41: TRUE
A42: K012 | B42: C | C42: 44172 | D42: 120 | E42: 5 | F42: FALSE
A43: K013 | B43: A | C43: 44203 | D43: 130 | E43: 6 | F43: TRUE
A44: K014 | B44: B | C44: 44234 | D44: 140 | E44: 7 | F44: FALSE
...

Sheet Arithmetic
A1: Arithmetic — CellRune Excel Oracle
A2: Blue cells are formulas. Gray rows are catalogued exclusions. Excel must recalculate and save cached values. | R2: Catalog rows | S2: =COUNTA(A5:A166) -> 162
R3: Primary cases | S3: =COUNTA(A5:A166) -> 162
A4: Case ID | B4: Category | C4: Function | D4: Scenario | E4: Formula text | F4: Result / spill zone | M4: Expectation | N4: Sentinel | O4: Note | P4: Dependency signature | R4: Active formulas | S4: =COUNTA(A5:A166)-COUNTIF(M5:M166,"excluded") -> 162
A5: function:abs | B5: Math and trigonometry | C5: ABS | D5: Curated deterministic boundary with shared-data and cross-sheet inputs | E5: =ABS('SharedData'!$A$8) | F5: =ABS(SharedData!$A$8) -> 0.3 | M5: oracle_probe | N5: =IF(ISERROR(F5),"ERROR "&IFERROR(ERROR.TYPE(F5),""),"OK") -> OK | O5: Recalculate in Excel and compare the saved result. | P5: =IFERROR(N(F5),0)+SUM(SharedData!$A$6:$A$8)+ROW()/100000 -> 0.30005
A6: function:acos | B6: Math and trigonometry | C6: ACOS | D6: Function-catalog probe; genuine error results are retained as oracle evidence | E6: =ACOS(0.5) | F6: =ACOS(0.5) -> 1.0471976 | M6: oracle_probe | O6: Recalculate in Excel and compare the saved result.
A7: function:acosh | B7: Math and trigonometry | C7: ACOSH | D7: Function-catalog probe with a repaired call signature | E7: =ACOSH(2.5) | F7: =ACOSH(2.5) -> 1.5667992 | M7: oracle_probe | O7: Recalculate in Excel and compare the saved result.
A8: function:acot | B8: Math and trigonometry | C8: ACOT | D8: Function-catalog probe; genuine error results are retained as oracle evidence | E8: =ACOT(0.5) | F8: =_xlfn.ACOT(0.5) -> 1.1071487 | M8: oracle_probe | O8: Recalculate in Excel and compare the saved result.
A9: function:acoth | B9: Math and trigonometry | C9: ACOTH | D9: Function-catalog probe; genuine error results are retained as oracle evidence | E9: =ACOTH(0.5) | F9: =_xlfn.ACOTH(0.5) -> #NUM! | M9: oracle_probe | O9: Recalculate in Excel and compare the saved result.
A10: function:aggregate | B10: Math and trigonometry | C10: AGGREGATE | D10: Curated deterministic boundary with shared-data and cross-sheet inputs | E10: =AGGREGATE(9,6,'SharedData'!$E$6:$E$25) | F10: =_xlfn.AGGREGATE(9,6,SharedData!$E$6:$E$25) -> 2100 | M10: oracle_probe | O10: Recalculate in Excel and compare the saved result.
A11: function:arabic | B11: Math and trigonometry | C11: ARABIC | D11: Curated deterministic boundary with shared-data and cross-sheet inputs | E11: =ARABIC("MMXXVI") | F11: =_xlfn.ARABIC("MMXXVI") -> 2026 | M11: oracle_probe | O11: Recalculate in Excel and compare the saved result.
A12: function:asin | B12: Math and trigonometry | C12: ASIN | D12: Function-catalog probe; genuine error results are retained as oracle evidence | E12: =ASIN(0.5) | F12: =ASIN(0.5) -> 0.52359878 | M12: oracle_probe | O12: Recalculate in Excel and compare the saved result.
A13: function:asinh | B13: Math and trigonometry | C13: ASINH | D13: Function-catalog probe; genuine error results are retained as oracle evidence | E13: =ASINH(0.5) | F13: =ASINH(0.5) -> 0.48121183 | M13: oracle_probe | N13: =IF(ISERROR(F13),"ERROR "&IFERROR(ERROR.TYPE(F13),""),"OK") -> OK | O13: Recalculate in Excel and compare the saved result.
A14: function:atan | B14: Math and trigonometry | C14: ATAN | D14: Function-catalog probe; genuine error results are retained as oracle evidence | E14: =ATAN(0.5) | F14: =ATAN(0.5) -> 0.46364761 | M14: oracle_probe | O14: Recalculate in Excel and compare the saved result.
A15: function:atan2 | B15: Math and trigonometry | C15: ATAN2 | D15: Function-catalog probe with a repaired call signature | E15: =ATAN2(1,1) | F15: =ATAN2(1,1) -> 0.78539816 | M15: oracle_probe | O15: Recalculate in Excel and compare the saved result.
A16: function:atanh | B16: Math and trigonometry | C16: ATANH | D16: Function-catalog probe; genuine error results are retained as oracle evidence | E16: =ATANH(0.5) | F16: =ATANH(0.5) -> 0.54930614 | M16: oracle_probe | O16: Recalculate in Excel and compare the saved result.
A17: function:base | B17: Math and trigonometry | C17: BASE | D17: Curated deterministic boundary with shared-data and cross-sheet inputs | E17: =BASE(255,16,4) | F17: =_xlfn.BASE(255,16,4) -> 00FF | M17: oracle_probe | O17: Recalculate in Excel and compare the saved result. | P17: =IFERROR(N(F17),0)+SUM(SharedData!$A$6:$A$8)+ROW()/100000 -> 0.00017
A18: function:besseli | B18: Engineering | C18: BESSELI | D18: Curated deterministic boundary with shared-data and cross-sheet inputs | E18: =BESSELI(1.5,2) | F18: =BESSELI(1.5,2) -> 0.33783462 | M18: oracle_probe | O18: Recalculate in Excel and compare the saved result.
A19: function:besselj | B19: Engineering | C19: BESSELJ | D19: Curated deterministic boundary with shared-data and cross-sheet inputs | E19: =BESSELJ(1.5,2) | F19: =BESSELJ(1.5,2) -> 0.23208768 | M19: oracle_probe | O19: Recalculate in Excel and compare the saved result.
A20: function:besselk | B20: Engineering | C20: BESSELK | D20: Curated deterministic boundary with shared-data and cross-sheet inputs | E20: =BESSELK(1.5,2) | F20: =BESSELK(1.5,2) -> 0.58365597 | M20: oracle_probe | O20: Recalculate in Excel and compare the saved result.
A21: function:bessely | B21: Engineering | C21: BESSELY | D21: Curated deterministic boundary with shared-data and cross-sheet inputs | E21: =BESSELY(1.5,2) | F21: =BESSELY(1.5,2) -> -0.93219376 | M21: oracle_probe | N21: =IF(ISERROR(F21),"ERROR "&IFERROR(ERROR.TYPE(F21),""),"OK") -> OK | O21: Recalculate in Excel and compare the saved result.
A22: function:bin2dec | B22: Engineering | C22: BIN2DEC | D22: Curated deterministic boundary with shared-data and cross-sheet inputs | E22: =BIN2DEC("101101") | F22: =BIN2DEC("101101") -> 45 | M22: oracle_probe | O22: Recalculate in Excel and compare the saved result.
A23: function:bin2hex | B23: Engineering | C23: BIN2HEX | D23: Curated deterministic boundary with shared-data and cross-sheet inputs | E23: =BIN2HEX("101101",4) | F23: =BIN2HEX("101101",4) -> 002D | M23: oracle_probe | O23: Recalculate in Excel and compare the saved result.
A24: function:bin2oct | B24: Engineering | C24: BIN2OCT | D24: Curated deterministic boundary with shared-data and cross-sheet inputs | E24: =BIN2OCT("101101",4) | F24: =BIN2OCT("101101",4) -> 0055 | M24: oracle_probe | O24: Recalculate in Excel and compare the saved result.
A25: function:bitand | B25: Engineering | C25: BITAND | D25: Curated deterministic boundary with shared-data and cross-sheet inputs | E25: =BITAND(29,23) | F25: =_xlfn.BITAND(29,23) -> 21 | M25: oracle_probe | O25: Recalculate in Excel and compare the saved result.
A26: function:bitlshift | B26: Engineering | C26: BITLSHIFT | D26: Curated deterministic boundary with shared-data and cross-sheet inputs | E26: =BITLSHIFT(7,3) | F26: =_xlfn.BITLSHIFT(7,3) -> 56 | M26: oracle_probe | O26: Recalculate in Excel and compare the saved result.
A27: function:bitor | B27: Engineering | C27: BITOR | D27: Curated deterministic boundary with shared-data and cross-sheet inputs | E27: =BITOR(29,23) | F27: =_xlfn.BITOR(29,23) -> 31 | M27: oracle_probe | O27: Recalculate in Excel and compare the saved result.
A28: function:bitrshift | B28: Engineering | C28: BITRSHIFT | D28: Curated deterministic boundary with shared-data and cross-sheet inputs | E28: =BITRSHIFT(128,3) | F28: =_xlfn.BITRSHIFT(128,3) -> 16 | M28: oracle_probe | O28: Recalculate in Excel and compare the saved result.
A29: function:bitxor | B29: Engineering | C29: BITXOR | D29: Curated deterministic boundary with shared-data and cross-sheet inputs | E29: =BITXOR(29,23) | F29: =_xlfn.BITXOR(29,23) -> 10 | M29: oracle_probe | N29: =IF(ISERROR(F29),"ERROR "&IFERROR(ERROR.TYPE(F29),""),"OK") -> OK | O29: Recalculate in Excel and compare the saved result. | P29: =IFERROR(N(F29),0)+SUM(SharedData!$A$6:$A$8)+ROW()/100000 -> 10.00029
A30: function:ceiling | B30: Math and trigonometry | C30: CEILING | D30: Curated deterministic boundary with shared-data and cross-sheet inputs | E30: =CEILING('SharedData'!$A$19,0.25) | F30: =CEILING(SharedData!$A$19,0.25) -> 1.5 | M30: oracle_probe | O30: Recalculate in Excel and compare the saved result.
A31: function:ceiling-math | B31: Math and trigonometry | C31: CEILING.MATH | D31: Curated deterministic boundary with shared-data and cross-sheet inputs | E31: =CEILING.MATH('SharedData'!$A$19,0.25,1) | F31: =_xlfn.CEILING.MATH(SharedData!$A$19,0.25,1) -> 1.5 | M31: oracle_probe | O31: Recalculate in Excel and compare the saved result.
A32: function:ceiling-precise | B32: Math and trigonometry | C32: CEILING.PRECISE | D32: Curated deterministic boundary with shared-data and cross-sheet inputs | E32: =CEILING.PRECISE('SharedData'!$A$19,0.25) | F32: =_xlfn.CEILING.PRECISE(SharedData!$A$19,0.25) -> 1.5 | M32: oracle_probe | O32: Recalculate in Excel and compare the saved result.
A33: function:combin | B33: Math and trigonometry | C33: COMBIN | D33: Curated deterministic boundary with shared-data and cross-sheet inputs | E33: =COMBIN(10,3) | F33: =COMBIN(10,3) -> 120 | M33: oracle_probe | O33: Recalculate in Excel and compare the saved result.
A34: function:combina | B34: Math and trigonometry | C34: COMBINA | D34: Curated deterministic boundary with shared-data and cross-sheet inputs | E34: =COMBINA(10,3) | F34: =_xlfn.COMBINA(10,3) -> 220 | M34: oracle_probe | O34: Recalculate in Excel and compare the saved result.
A35: function:complex | B35: Engineering | C35: COMPLEX | D35: Curated deterministic boundary with shared-data and cross-sheet inputs | E35: =COMPLEX(3,4,"i") | F35: =COMPLEX(3,4,"i") -> 3+4i | M35: oracle_probe | O35: Recalculate in Excel and compare the saved result.
A36: function:convert | B36: Engineering | C36: CONVERT | D36: Curated deterministic boundary with shared-data and cross-sheet inputs | E36: =CONVERT(10,"km","mi") | F36: =CONVERT(10,"km","mi") -> 6.2137119 | M36: oracle_probe | O36: Recalculate in Excel and compare the saved result.
A37: function:cos | B37: Math and trigonometry | C37: COS | D37: Function-catalog probe; genuine error results are retained as oracle evidence | E37: =COS(0.5) | F37: =COS(0.5) -> 0.87758256 | M37: oracle_probe | N37: =IF(ISERROR(F37),"ERROR "&IFERROR(ERROR.TYPE(F37),""),"OK") -> OK | O37: Recalculate in Excel and compare the saved result.
A38: function:cosh | B38: Math and trigonometry | C38: COSH | D38: Function-catalog probe; genuine error results are retained as oracle evidence | E38: =COSH(0.5) | F38: =COSH(0.5) -> 1.127626 | M38: oracle_probe | O38: Recalculate in Excel and compare the saved result.
A39: function:cot | B39: Math and trigonometry | C39: COT | D39: Function-catalog probe; genuine error results are retained as oracle evidence | E39: =COT(0.5) | F39: =_xlfn.COT(0.5) -> 1.8304877 | M39: oracle_probe | O39: Recalculate in Excel and compare the saved result.
A40: function:coth | B40: Math and trigonometry | C40: COTH | D40: Function-catalog probe; genuine error results are retained as oracle evidence | E40: =COTH(0.5) | F40: =_xlfn.COTH(0.5) -> 2.1639534 | M40: oracle_probe | O40: Recalculate in Excel and compare the saved result.
...

Sheet Aggregates
A1: Aggregates — CellRune Excel Oracle
A2: Blue cells are formulas. Gray rows are catalogued exclusions. Excel must recalculate and save cached values. | R2: Catalog rows | S2: =COUNTA(A5:A178) -> 174
R3: Primary cases | S3: =COUNTA(A5:A178) -> 174
A4: Case ID | B4: Category | C4: Function | D4: Scenario | E4: Formula text | F4: Result / spill zone | M4: Expectation | N4: Sentinel | O4: Note | P4: Dependency signature | R4: Active formulas | S4: =COUNTA(A5:A178)-COUNTIF(M5:M178,"excluded") -> 174
A5: function:avedev | B5: Statistical | C5: AVEDEV | D5: Function-catalog probe; genuine error results are retained as oracle evidence | E5: =AVEDEV('SharedData'!$E$6:$E$25) | F5: =AVEDEV(SharedData!$E$6:$E$25) -> 50 | M5: oracle_probe | N5: =IF(ISERROR(F5),"ERROR "&IFERROR(ERROR.TYPE(F5),""),"OK") -> OK | O5: Recalculate in Excel and compare the saved result. | P5: =IFERROR(N(F5),0)+IFERROR(N(Arithmetic!$F$5),0)+ROW()/100000 -> 50.30005
A6: function:average | B6: Statistical | C6: AVERAGE | D6: Function-catalog probe; genuine error results are retained as oracle evidence | E6: =AVERAGE('SharedData'!$E$6:$E$25) | F6: =AVERAGE(SharedData!$E$6:$E$25) -> 105 | M6: oracle_probe | O6: Recalculate in Excel and compare the saved result.
A7: function:averagea | B7: Statistical | C7: AVERAGEA | D7: Function-catalog probe; genuine error results are retained as oracle evidence | E7: =AVERAGEA('SharedData'!$E$6:$E$25) | F7: =AVERAGEA(SharedData!$E$6:$E$25) -> 105 | M7: oracle_probe | O7: Recalculate in Excel and compare the saved result.
A8: function:averageif | B8: Statistical | C8: AVERAGEIF | D8: Curated deterministic boundary with shared-data and cross-sheet inputs | E8: =AVERAGEIF('SharedData'!$C$6:$C$25,"A",'SharedData'!$E$6:$E$25) | F8: =AVERAGEIF(SharedData!$C$6:$C$25,"A",SharedData!$E$6:$E$25) -> 100 | M8: oracle_probe | O8: Recalculate in Excel and compare the saved result.
A9: function:averageifs | B9: Statistical | C9: AVERAGEIFS | D9: Curated deterministic boundary with shared-data and cross-sheet inputs | E9: =AVERAGEIFS('SharedData'!$E$6:$E$25,'SharedData'!$C$6:$C$25,"A",'SharedData'!$F$6:$F$25,">5") | F9: =AVERAGEIFS(SharedData!$E$6:$E$25,SharedData!$C$6:$C$25,"A",SharedData!$F$6:$F$25,">5") -> 100 | M9: oracle_probe | O9: Recalculate in Excel and compare the saved result.
A10: function:beta-dist | B10: Statistical | C10: BETA.DIST | D10: Function-catalog probe with a repaired call signature | E10: =BETA.DIST(0.6,8,10,TRUE,0,1) | F10: =_xlfn.BETA.DIST(0.6,8,10,TRUE,0,1) -> 0.90810075 | M10: oracle_probe | O10: Recalculate in Excel and compare the saved result.
A11: function:beta-inv | B11: Statistical | C11: BETA.INV | D11: Function-catalog probe with a repaired call signature | E11: =BETA.INV(0.6,8,10,0,1) | F11: =_xlfn.BETA.INV(0.6,8,10,0,1) -> 0.47252659 | M11: oracle_probe | O11: Recalculate in Excel and compare the saved result.
A12: function:betadist | B12: Statistical | C12: BETADIST | D12: Curated deterministic boundary with shared-data and cross-sheet inputs | E12: =BETADIST(0.5,2,3,0,1) | F12: =BETADIST(0.5,2,3,0,1) -> 0.6875 | M12: oracle_probe | O12: Recalculate in Excel and compare the saved result.
A13: function:betainv | B13: Statistical | C13: BETAINV | D13: Curated deterministic boundary with shared-data and cross-sheet inputs | E13: =BETAINV(0.5,2,3,0,1) | F13: =BETAINV(0.5,2,3,0,1) -> 0.38572757 | M13: oracle_probe | N13: =IF(ISERROR(F13),"ERROR "&IFERROR(ERROR.TYPE(F13),""),"OK") -> OK | O13: Recalculate in Excel and compare the saved result.
A14: function:binom-dist | B14: Statistical | C14: BINOM.DIST | D14: Curated deterministic boundary with shared-data and cross-sheet inputs | E14: =BINOM.DIST(3,10,0.4,FALSE) | F14: =_xlfn.BINOM.DIST(3,10,0.4,FALSE) -> 0.21499085 | M14: oracle_probe | O14: Recalculate in Excel and compare the saved result.
A15: function:binom-dist-range | B15: Statistical | C15: BINOM.DIST.RANGE | D15: Curated deterministic boundary with shared-data and cross-sheet inputs | E15: =BINOM.DIST.RANGE(10,0.4,3,6) | F15: =_xlfn.BINOM.DIST.RANGE(10,0.4,3,6) -> 0.77794836 | M15: oracle_probe | O15: Recalculate in Excel and compare the saved result.
A16: function:binom-inv | B16: Statistical | C16: BINOM.INV | D16: Curated deterministic boundary with shared-data and cross-sheet inputs | E16: =BINOM.INV(10,0.4,0.6) | F16: =_xlfn.BINOM.INV(10,0.4,0.6) -> 4 | M16: oracle_probe | O16: Recalculate in Excel and compare the saved result.
A17: function:binomdist | B17: Statistical | C17: BINOMDIST | D17: Curated deterministic boundary with shared-data and cross-sheet inputs | E17: =BINOMDIST(3,10,0.4,FALSE) | F17: =BINOMDIST(3,10,0.4,FALSE) -> 0.21499085 | M17: oracle_probe | O17: Recalculate in Excel and compare the saved result. | P17: =IFERROR(N(F17),0)+IFERROR(N(Arithmetic!$F$5),0)+ROW()/100000 -> 0.51516085
A18: function:chidist | B18: Statistical | C18: CHIDIST | D18: Curated deterministic boundary with shared-data and cross-sheet inputs | E18: =CHIDIST(4,3) | F18: =CHIDIST(4,3) -> 0.26146413 | M18: oracle_probe | O18: Recalculate in Excel and compare the saved result.
A19: function:chiinv | B19: Statistical | C19: CHIINV | D19: Curated deterministic boundary with shared-data and cross-sheet inputs | E19: =CHIINV(0.05,3) | F19: =CHIINV(0.05,3) -> 7.8147279 | M19: oracle_probe | O19: Recalculate in Excel and compare the saved result.
A20: function:chisq-dist | B20: Statistical | C20: CHISQ.DIST | D20: Curated deterministic boundary with shared-data and cross-sheet inputs | E20: =CHISQ.DIST(4,3,TRUE) | F20: =_xlfn.CHISQ.DIST(4,3,TRUE) -> 0.73853587 | M20: oracle_probe | O20: Recalculate in Excel and compare the saved result.
A21: function:chisq-dist-rt | B21: Statistical | C21: CHISQ.DIST.RT | D21: Curated deterministic boundary with shared-data and cross-sheet inputs | E21: =CHISQ.DIST.RT(4,3) | F21: =_xlfn.CHISQ.DIST.RT(4,3) -> 0.26146413 | M21: oracle_probe | N21: =IF(ISERROR(F21),"ERROR "&IFERROR(ERROR.TYPE(F21),""),"OK") -> OK | O21: Recalculate in Excel and compare the saved result.
A22: function:chisq-inv | B22: Statistical | C22: CHISQ.INV | D22: Curated deterministic boundary with shared-data and cross-sheet inputs | E22: =CHISQ.INV(0.95,3) | F22: =_xlfn.CHISQ.INV(0.95,3) -> 7.8147279 | M22: oracle_probe | O22: Recalculate in Excel and compare the saved result.
A23: function:chisq-inv-rt | B23: Statistical | C23: CHISQ.INV.RT | D23: Curated deterministic boundary with shared-data and cross-sheet inputs | E23: =CHISQ.INV.RT(0.05,3) | F23: =_xlfn.CHISQ.INV.RT(0.05,3) -> 7.8147279 | M23: oracle_probe | O23: Recalculate in Excel and compare the saved result.
A24: function:chisq-test | B24: Statistical | C24: CHISQ.TEST | D24: Curated deterministic boundary with shared-data and cross-sheet inputs | E24: =CHISQ.TEST('SharedData'!$E$6:$F$8,'SharedData'!$I$6:$J$8) | F24: =_xlfn.CHISQ.TEST(SharedData!$E$6:$F$8,SharedData!$I$6:$J$8) -> 1.3410807e-108 | M24: oracle_probe | O24: Recalculate in Excel and compare the saved result.
A25: function:chitest | B25: Statistical | C25: CHITEST | D25: Curated deterministic boundary with shared-data and cross-sheet inputs | E25: =CHITEST('SharedData'!$E$6:$F$8,'SharedData'!$I$6:$J$8) | F25: =CHITEST(SharedData!$E$6:$F$8,SharedData!$I$6:$J$8) -> 1.3410807e-108 | M25: oracle_probe | O25: Recalculate in Excel and compare the saved result.
A26: function:confidence | B26: Statistical | C26: CONFIDENCE | D26: Curated deterministic boundary with shared-data and cross-sheet inputs | E26: =CONFIDENCE(0.05,2.5,100) | F26: =CONFIDENCE(0.05,2.5,100) -> 0.489991 | M26: oracle_probe | O26: Recalculate in Excel and compare the saved result.
A27: function:confidence-norm | B27: Statistical | C27: CONFIDENCE.NORM | D27: Curated deterministic boundary with shared-data and cross-sheet inputs | E27: =CONFIDENCE.NORM(0.05,2.5,100) | F27: =_xlfn.CONFIDENCE.NORM(0.05,2.5,100) -> 0.489991 | M27: oracle_probe | O27: Recalculate in Excel and compare the saved result.
A28: function:confidence-t | B28: Statistical | C28: CONFIDENCE.T | D28: Curated deterministic boundary with shared-data and cross-sheet inputs | E28: =CONFIDENCE.T(0.05,2.5,100) | F28: =_xlfn.CONFIDENCE.T(0.05,2.5,100) -> 0.49605424 | M28: oracle_probe | O28: Recalculate in Excel and compare the saved result.
A29: function:correl | B29: Statistical | C29: CORREL | D29: Curated deterministic boundary with shared-data and cross-sheet inputs | E29: =CORREL('SharedData'!$I$6:$I$25,'SharedData'!$J$6:$J$25) | F29: =CORREL(SharedData!$I$6:$I$25,SharedData!$J$6:$J$25) -> 1 | M29: oracle_probe | N29: =IF(ISERROR(F29),"ERROR "&IFERROR(ERROR.TYPE(F29),""),"OK") -> OK | O29: Recalculate in Excel and compare the saved result. | P29: =IFERROR(N(F29),0)+IFERROR(N(Arithmetic!$F$17),0)+ROW()/100000 -> 1.00029
A30: function:count | B30: Statistical | C30: COUNT | D30: Function-catalog probe; genuine error results are retained as oracle evidence | E30: =COUNT('SharedData'!$E$6:$E$25) | F30: =COUNT(SharedData!$E$6:$E$25) -> 20 | M30: oracle_probe | O30: Recalculate in Excel and compare the saved result.
A31: function:counta | B31: Statistical | C31: COUNTA | D31: Function-catalog probe; genuine error results are retained as oracle evidence | E31: =COUNTA('SharedData'!$E$6:$E$25) | F31: =COUNTA(SharedData!$E$6:$E$25) -> 20 | M31: oracle_probe | O31: Recalculate in Excel and compare the saved result.
A32: function:countblank | B32: Statistical | C32: COUNTBLANK | D32: Function-catalog probe; genuine error results are retained as oracle evidence | E32: =COUNTBLANK('SharedData'!$E$6:$E$25) | F32: =COUNTBLANK(SharedData!$E$6:$E$25) -> 0 | M32: oracle_probe | O32: Recalculate in Excel and compare the saved result.
A33: function:countif | B33: Statistical | C33: COUNTIF | D33: Curated deterministic boundary with shared-data and cross-sheet inputs | E33: =COUNTIF('SharedData'!$C$6:$C$25,"A") | F33: =COUNTIF(SharedData!$C$6:$C$25,"A") -> 7 | M33: oracle_probe | O33: Recalculate in Excel and compare the saved result.
A34: function:countifs | B34: Statistical | C34: COUNTIFS | D34: Curated deterministic boundary with shared-data and cross-sheet inputs | E34: =COUNTIFS('SharedData'!$C$6:$C$25,"A",'SharedData'!$E$6:$E$25,">50") | F34: =COUNTIFS(SharedData!$C$6:$C$25,"A",SharedData!$E$6:$E$25,">50") -> 5 | M34: oracle_probe | O34: Recalculate in Excel and compare the saved result.
A35: function:covar | B35: Statistical | C35: COVAR | D35: Curated deterministic boundary with shared-data and cross-sheet inputs | E35: =COVAR('SharedData'!$I$6:$I$25,'SharedData'!$J$6:$J$25) | F35: =COVAR(SharedData!$I$6:$I$25,SharedData!$J$6:$J$25) -> 66.5 | M35: oracle_probe | O35: Recalculate in Excel and compare the saved result.
A36: function:covariance-p | B36: Statistical | C36: COVARIANCE.P | D36: Curated deterministic boundary with shared-data and cross-sheet inputs | E36: =COVARIANCE.P('SharedData'!$I$6:$I$25,'SharedData'!$J$6:$J$25) | F36: =_xlfn.COVARIANCE.P(SharedData!$I$6:$I$25,SharedData!$J$6:$J$25) -> 66.5 | M36: oracle_probe | O36: Recalculate in Excel and compare the saved result.
A37: function:covariance-s | B37: Statistical | C37: COVARIANCE.S | D37: Curated deterministic boundary with shared-data and cross-sheet inputs | E37: =COVARIANCE.S('SharedData'!$I$6:$I$25,'SharedData'!$J$6:$J$25) | F37: =_xlfn.COVARIANCE.S(SharedData!$I$6:$I$25,SharedData!$J$6:$J$25) -> 70 | M37: oracle_probe | N37: =IF(ISERROR(F37),"ERROR "&IFERROR(ERROR.TYPE(F37),""),"OK") -> OK | O37: Recalculate in Excel and compare the saved result.
A38: function:critbinom | B38: Statistical | C38: CRITBINOM | D38: Curated deterministic boundary with shared-data and cross-sheet inputs | E38: =CRITBINOM(10,0.4,0.6) | F38: =CRITBINOM(10,0.4,0.6) -> 4 | M38: oracle_probe | O38: Recalculate in Excel and compare the saved result.
A39: function:daverage | B39: Database | C39: DAVERAGE | D39: Function-catalog probe; genuine error results are retained as oracle evidence | E39: =DAVERAGE('SharedData'!$A$30:$F$50,"Amount",'SharedData'!$H$30:$I$32) | F39: =DAVERAGE(SharedData!$A$30:$F$50,"Amount",SharedData!$H$30:$I$32) -> 101.11111 | M39: oracle_probe | O39: Recalculate in Excel and compare the saved result.
A40: function:dcount | B40: Database | C40: DCOUNT | D40: Function-catalog probe; genuine error results are retained as oracle evidence | E40: =DCOUNT('SharedData'!$A$30:$F$50,"Amount",'SharedData'!$H$30:$I$32) | F40: =DCOUNT(SharedData!$A$30:$F$50,"Amount",SharedData!$H$30:$I$32) -> 9 | M40: oracle_probe | O40: Recalculate in Excel and compare the saved result.
...

Sheet ArraysCSE
A1: ArraysCSE — CellRune Excel Oracle
A2: Blue cells are formulas. Gray rows are catalogued exclusions. Excel must recalculate and save cached values. | R2: Catalog rows | S2: =COUNTA(A5:A80) -> 16
R3: Primary cases | S3: =COUNTA(A5:A80) -> 16
A4: Case ID | B4: Category | C4: Function | D4: Scenario | E4: Formula text | F4: Result / spill zone | M4: Expectation | N4: Sentinel | O4: Note | P4: Dependency signature | R4: Active formulas | S4: =COUNTA(A5:A80)-COUNTIF(M5:M80,"excluded") -> 16
A5: curated:arrayscse:c001 | B5: Curated behaviour | C5: CURATED | D5: Hand-picked semantic boundary named by the oracle plan | E5: =SUM(IF('SharedData'!$C$6:$C$25="A",'SharedData'!$E$6:$E$25,0)) | F5: {=SUM(IF(SharedData!$C$6:$C$25="A",SharedData!$E$6:$E$25,0))} -> 700 | M5: oracle_probe | N5: =IF(ISERROR(F5),"ERROR "&IFERROR(ERROR.TYPE(F5),""),"OK") -> OK | O5: Uses only deterministic workbook inputs; result must be cached by Excel. | P5: =IFERROR(N(F5),0)+IFERROR(N(Aggregates!$F$5),0)+ROW()/100000 -> 750.00005
A10: curated:arrayscse:c002 | B10: Curated behaviour | C10: CURATED | D10: Hand-picked semantic boundary named by the oracle plan | E10: =SUM(IF('SharedData'!$G$6:$G$25,'SharedData'!$E$6:$E$25*'SharedData'!$F$6:$F$25,0)) | F10: {=SUM(IF(SharedData!$G$6:$G$25,SharedData!$E$6:$E$25*SharedData!$F$6:$F$25,0))} -> 3850 | M10: oracle_probe | O10: Uses only deterministic workbook inputs; result must be cached by Excel.
A15: curated:arrayscse:c003 | B15: Curated behaviour | C15: CURATED | D15: Hand-picked semantic boundary named by the oracle plan | E15: =IF({1,0,1;0,1,0;1,1,0},{10,20,30;40,50,60;70,80,90},NA()) | F15: {=IF({1,0,1;0,1,0;1,1,0},{10,20,30;40,50,60;70,80,90},NA())} -> 10 | G15: #N/A | H15: 30 | M15: oracle_probe | O15: Uses only deterministic workbook inputs; result must be cached by Excel.
F16: #N/A | G16: 50 | H16: #N/A
F17: 70 | G17: 80 | H17: #N/A
A20: curated:arrayscse:c004 | B20: Curated behaviour | C20: CURATED | D20: Hand-picked semantic boundary named by the oracle plan | E20: ={1,2,3}*{1;10;100} | F20: {={1,2,3}*{1;10;100}} -> 1 | G20: 2 | H20: 3 | M20: oracle_probe | O20: Uses only deterministic workbook inputs; result must be cached by Excel.
F21: 10 | G21: 20 | H21: 30
F22: 100 | G22: 200 | H22: 300
A25: curated:arrayscse:c005 | B25: Curated behaviour | C25: CURATED | D25: Hand-picked semantic boundary named by the oracle plan | E25: ={1,2,3,4}*{1;2;3} | F25: {={1,2,3,4}*{1;2;3}} -> 1 | G25: 2 | H25: 3 | I25: 4 | M25: oracle_probe | O25: Uses only deterministic workbook inputs; result must be cached by Excel.
F26: 2 | G26: 4 | H26: 6 | I26: 8
F27: 3 | G27: 6 | H27: 9 | I27: 12
A30: curated:arrayscse:c006 | B30: Curated behaviour | C30: CURATED | D30: Hand-picked semantic boundary named by the oracle plan | E30: =IF({TRUE,FALSE;FALSE,TRUE},{"text",2;TRUE,45351},NA()) | F30: {=IF({TRUE,FALSE;FALSE,TRUE},{"text",2;TRUE,45351},NA())} -> text | G30: #N/A | M30: oracle_probe | O30: Uses only deterministic workbook inputs; result must be cached by Excel.
F31: #N/A | G31: 45351
A35: curated:arrayscse:c007 | B35: Curated behaviour | C35: CURATED | D35: Hand-picked semantic boundary named by the oracle plan | E35: ={1,2,3}+{1,2} | F35: {={1,2,3}+{1,2}} -> 2 | G35: 4 | H35: #N/A | M35: oracle_probe | O35: Uses only deterministic workbook inputs; result must be cached by Excel.
A40: curated:arrayscse:c008 | B40: Curated behaviour | C40: CURATED | D40: Hand-picked semantic boundary named by the oracle plan | E40: ={10,20} | F40: {={10,20}} -> 10 | G40: 20 | H40: #N/A | M40: oracle_probe | O40: Uses only deterministic workbook inputs; result must be cached by Excel.
A45: curated:arrayscse:c009 | B45: Curated behaviour | C45: CURATED | D45: Hand-picked semantic boundary named by the oracle plan | E45: ={1,2;3,4}+{10,20,30;40,50,60} | F45: {={1,2;3,4}+{10,20,30;40,50,60}} -> 11 | G45: 22 | H45: #N/A | M45: oracle_probe | N45: =IF(ISERROR(F45),"ERROR "&IFERROR(ERROR.TYPE(F45),""),"OK") -> OK | O45: Uses only deterministic workbook inputs; result must be cached by Excel.
F46: 43 | G46: 54 | H46: #N/A
A50: curated:arrayscse:c010 | B50: Curated behaviour | C50: CURATED | D50: Hand-picked semantic boundary named by the oracle plan | E50: =MMULT({1,2,3;4,5,6},{7,8;9,10;11,12}) | F50: {=MMULT({1,2,3;4,5,6},{7,8;9,10;11,12})} -> 58 | G50: 64 | M50: oracle_probe | O50: Uses only deterministic workbook inputs; result must be cached by Excel.
F51: 139 | G51: 154
A55: curated:arrayscse:c011 | B55: Curated behaviour | C55: CURATED | D55: Hand-picked semantic boundary named by the oracle plan | E55: =TRANSPOSE('SharedData'!$A$6:$C$8) | F55: {=TRANSPOSE(SharedData!$A$6:$C$8)} -> 0.1 | G55: 0.2 | H55: -0.3 | M55: oracle_probe | O55: Uses only deterministic workbook inputs; result must be cached by Excel.
F56: K001 | G56: K002 | H56: K003
F57: A | G57: B | H57: C
A60: curated:arrayscse:c012 | B60: Curated behaviour | C60: CURATED | D60: Hand-picked semantic boundary named by the oracle plan | E60: =SUM(IF(ISNUMBER('SharedData'!$A$6:$H$25),'SharedData'!$A$6:$H$25,0)) | F60: {=SUM(IF(ISNUMBER(SharedData!$A$6:$H$25),SharedData!$A$6:$H$25,0))} -> 884842.65 | M60: oracle_probe | O60: Uses only deterministic workbook inputs; result must be cached by Excel.
A65: curated:arrayscse:c013 | B65: Curated behaviour | C65: CURATED | D65: Hand-picked semantic boundary named by the oracle plan | E65: =SUM(IF('SharedData'!$H$6:$H$25="text",1,0)) | F65: {=SUM(IF(SharedData!$H$6:$H$25="text",1,0))} -> 2 | M65: oracle_probe | O65: Uses only deterministic workbook inputs; result must be cached by Excel. | P65: =IFERROR(N(F65),0)+IFERROR(N(Aggregates!$F$5),0)+ROW()/100000 -> 52.00065
A70: curated:arrayscse:c014 | B70: Curated behaviour | C70: CURATED | D70: Hand-picked semantic boundary named by the oracle plan | E70: =INDEX('SharedData'!$A$6:$F$25,{1;5;10},{1,3,5}) | F70: {=INDEX(SharedData!$A$6:$F$25,{1;5;10},{1,3,5})} -> 0.1 | G70: A | H70: 10 | M70: oracle_probe | O70: Uses only deterministic workbook inputs; result must be cached by Excel.
F71: 2 | G71: B | H71: 50
F72: -10 | G72: A | H72: 100
A75: curated:arrayscse:c015 | B75: Curated behaviour | C75: CURATED | D75: Hand-picked semantic boundary named by the oracle plan | E75: =IF({1,0,1,0,1},'SharedData'!$E$6:$E$10,'SharedData'!$B$6:$B$10) | F75: {=IF({1,0,1,0,1},SharedData!$E$6:$E$10,SharedData!$B$6:$B$10)} -> 10 | G75: K001 | H75: 10 | I75: K001 | J75: 10 | M75: oracle_probe | O75: Uses only deterministic workbook inputs; result must be cached by Excel.
A80: curated:arrayscse:c016 | B80: Curated behaviour | C80: CURATED | D80: Hand-picked semantic boundary named by the oracle plan | E80: =SUM({1,2,3}*{1;10;100}) | F80: {=SUM({1,2,3}*{1;10;100})} -> 666 | M80: oracle_probe | O80: Uses only deterministic workbook inputs; result must be cached by Excel.

Sheet ArraysDynamic
A1: ArraysDynamic — CellRune Excel Oracle
A2: Blue cells are formulas. Gray rows are catalogued exclusions. Excel must recalculate and save cached values. | R2: Catalog rows | S2: =COUNTA(A5:A1541) -> 65
R3: Primary cases | S3: =COUNTA(A5:A1541) -> 65
A4: Case ID | B4: Category | C4: Function | D4: Scenario | E4: Formula text | F4: Result / spill zone | M4: Expectation | N4: Sentinel | O4: Note | P4: Dependency signature | R4: Active formulas | S4: =COUNTA(A5:A1541)-COUNTIF(M5:M1541,"excluded") -> 65
A5: function:bycol | B5: Dynamic array / Lambda | C5: BYCOL | D5: Curated deterministic boundary with shared-data and cross-sheet inputs | E5: =BYCOL('SharedData'!$E$6:$F$10,LAMBDA(col,SUM(col))) | F5: {=_xlfn.BYCOL(SharedData!$E$6:$F$10,_xlfn.LAMBDA(_xlpm.col,SUM(_xlpm.col)))} -> 150 | G5: 15 | M5: oracle_probe | N5: =IF(ISERROR(F5),"ERROR "&IFERROR(ERROR.TYPE(F5),""),"OK") -> OK | O5: Recalculate in Excel and compare the saved result. | P5: =IFERROR(N(F5),0)+IFERROR(N(ArraysCSE!$F$5),0)+ROW()/100000 -> 850.00005
A29: function:byrow | B29: Dynamic array / Lambda | C29: BYROW | D29: Curated deterministic boundary with shared-data and cross-sheet inputs | E29: =BYROW('SharedData'!$E$6:$F$10,LAMBDA(row,SUM(row))) | F29: {=_xlfn.BYROW(SharedData!$E$6:$F$10,_xlfn.LAMBDA(_xlpm.row,SUM(_xlpm.row)))} -> 11 | M29: oracle_probe | O29: Recalculate in Excel and compare the saved result.
F30: 22
F31: 33
F32: 44
F33: 55
A53: function:choosecols | B53: Dynamic array / Lambda | C53: CHOOSECOLS | D53: Curated deterministic boundary with shared-data and cross-sheet inputs | E53: =CHOOSECOLS('SharedData'!$A$6:$F$10,1,3,5) | F53: {=_xlfn.CHOOSECOLS(SharedData!$A$6:$F$10,1,3,5)} -> 0.1 | G53: A | H53: 10 | M53: oracle_probe | O53: Recalculate in Excel and compare the saved result.
F54: 0.2 | G54: B | H54: 20
F55: -0.3 | G55: C | H55: 30
F56: 1 | G56: A | H56: 40
F57: 2 | G57: B | H57: 50
A77: function:chooserows | B77: Dynamic array / Lambda | C77: CHOOSEROWS | D77: Curated deterministic boundary with shared-data and cross-sheet inputs | E77: =CHOOSEROWS('SharedData'!$A$6:$F$10,1,3,5) | F77: {=_xlfn.CHOOSEROWS(SharedData!$A$6:$F$10,1,3,5)} -> 0.1 | G77: K001 | H77: A | I77: 43831 | J77: 10 | K77: 1 | M77: oracle_probe | O77: Recalculate in Excel and compare the saved result.
F78: -0.3 | G78: K003 | H78: C | I78: 43893 | J78: 30 | K78: 3
F79: 2 | G79: K005 | H79: B | I79: 43955 | J79: 50 | K79: 5
A101: function:drop | B101: Dynamic array / Lambda | C101: DROP | D101: Curated deterministic boundary with shared-data and cross-sheet inputs | E101: =DROP('SharedData'!$A$6:$F$15,2,1) | F101: {=_xlfn.DROP(SharedData!$A$6:$F$15,2,1)} -> K003 | G101: C | H101: 43893 | I101: 30 | J101: 3 | M101: oracle_probe | O101: Recalculate in Excel and compare the saved result.
F102: K004 | G102: A | H102: 43924 | I102: 40 | J102: 4
F103: K005 | G103: B | H103: 43955 | I103: 50 | J103: 5
F104: K006 | G104: C | H104: 43986 | I104: 60 | J104: 6
F105: K007 | G105: A | H105: 44017 | I105: 70 | J105: 7
F106: K008 | G106: B | H106: 44048 | I106: 80 | J106: 1
F107: K009 | G107: C | H107: 44079 | I107: 90 | J107: 2
F108: K010 | G108: A | H108: 44110 | I108: 100 | J108: 3
A125: function:expand | B125: Dynamic array / Lambda | C125: EXPAND | D125: Curated deterministic boundary with shared-data and cross-sheet inputs | E125: =EXPAND('SharedData'!$A$6:$B$8,5,4,"pad") | F125: {=_xlfn.EXPAND(SharedData!$A$6:$B$8,5,4,"pad")} -> 0.1 | G125: K001 | H125: pad | I125: pad | M125: oracle_probe | O125: Recalculate in Excel and compare the saved result.
F126: 0.2 | G126: K002 | H126: pad | I126: pad
F127: -0.3 | G127: K003 | H127: pad | I127: pad
F128: pad | G128: pad | H128: pad | I128: pad
F129: pad | G129: pad | H129: pad | I129: pad
A149: function:filter | B149: Dynamic array / Lambda | C149: FILTER | D149: Curated deterministic boundary with shared-data and cross-sheet inputs | E149: =FILTER('SharedData'!$A$6:$E$25,'SharedData'!$C$6:$C$25="A","none") | F149: {=_xlfn._xlws.FILTER(SharedData!$A$6:$E$25,SharedData!$C$6:$C$25="A","none")} -> 0.1 | G149: K001 | H149: A | I149: 43831 | J149: 10 | M149: oracle_probe | O149: Recalculate in Excel and compare the saved result.
F150: 1 | G150: K004 | H150: A | I150: 43924 | J150: 40
F151: 4 | G151: K007 | H151: A | I151: 44017 | J151: 70
F152: -10 | G152: K010 | H152: A | I152: 44110 | J152: 100
F153: 0 | G153: K013 | H153: A | I153: 44203 | J153: 130
F154: 3.5 | G154: K016 | H154: A | I154: 44296 | J154: 160
F155: 0.05 | G155: K019 | H155: A | I155: 44389 | J155: 190
A173: function:frequency | B173: Dynamic array / Lambda | C173: FREQUENCY | D173: Curated deterministic boundary with shared-data and cross-sheet inputs | E173: =FREQUENCY('SharedData'!$E$6:$E$25,{50,100,150}) | F173: {=FREQUENCY(SharedData!$E$6:$E$25,{50,100,150})} -> 5 | M173: oracle_probe | O173: Recalculate in Excel and compare the saved result.
F174: 5
...

Sheet Intersection
A1: Intersection — CellRune Excel Oracle
A2: Blue cells are formulas. Gray rows are catalogued exclusions. Excel must recalculate and save cached values. | R2: Catalog rows | S2: =COUNTA(A5:A15) -> 11
R3: Primary cases | S3: =COUNTA(A5:A15) -> 11
A4: Case ID | B4: Category | C4: Function | D4: Scenario | E4: Formula text | F4: Result / spill zone | M4: Expectation | N4: Sentinel | O4: Note | P4: Dependency signature | R4: Active formulas | S4: =COUNTA(A5:A15)-COUNTIF(M5:M15,"excluded") -> 11
A5: curated:intersection:c001 | B5: Curated behaviour | C5: CURATED | D5: Hand-picked semantic boundary named by the oracle plan | E5: =@'SharedData'!A6:A25 | F5: =SharedData!A6:A25 -> #VALUE! | M5: oracle_probe | N5: =IF(ISERROR(F5),"ERROR "&IFERROR(ERROR.TYPE(F5),""),"OK") -> ERROR 3 | O5: Uses only deterministic workbook inputs; result must be cached by Excel. | P5: =IFERROR(N(F5),0)+IFERROR(N(ArraysDynamic!$F$5),0)+ROW()/100000 -> 150.00005
A6: curated:intersection:c002 | B6: Curated behaviour | C6: CURATED | D6: Hand-picked semantic boundary named by the oracle plan | E6: =@('SharedData'!A6:A25) | F6: =_xlfn.SINGLE((SharedData!A6:A25)) -> 0.1 | M6: oracle_probe | O6: Uses only deterministic workbook inputs; result must be cached by Excel.
A7: curated:intersection:c003 | B7: Curated behaviour | C7: CURATED | D7: Hand-picked semantic boundary named by the oracle plan | E7: =@('SharedData'!A:A) | F7: =_xlfn.SINGLE((SharedData!A:A)) -> 0.2 | M7: oracle_probe | O7: Uses only deterministic workbook inputs; result must be cached by Excel.
A8: curated:intersection:c004 | B8: Curated behaviour | C8: CURATED | D8: Hand-picked semantic boundary named by the oracle plan | E8: =@(@'SharedData'!A6:A8) | F8: =_xlfn.SINGLE((_xlfn.SINGLE(SharedData!A6:A8))) -> -0.3 | M8: oracle_probe | O8: Uses only deterministic workbook inputs; result must be cached by Excel.
A9: curated:intersection:c005 | B9: Curated behaviour | C9: CURATED | D9: Hand-picked semantic boundary named by the oracle plan | E9: =@'SharedData'!A6:C6 | F9: =SharedData!A6:C6 -> #VALUE! | M9: oracle_probe | O9: Uses only deterministic workbook inputs; result must be cached by Excel.
A10: curated:intersection:c006 | B10: Curated behaviour | C10: CURATED | D10: Hand-picked semantic boundary named by the oracle plan | E10: =SUM('SharedData'!A6:A20 'SharedData'!A12:C12) | F10: =SUM(SharedData!A6:A20 SharedData!A12:C12) -> 4 | M10: oracle_probe | O10: Uses only deterministic workbook inputs; result must be cached by Excel.
A11: curated:intersection:c007 | B11: Curated behaviour | C11: CURATED | D11: Hand-picked semantic boundary named by the oracle plan | E11: =SUM(('SharedData'!A6:A8,'SharedData'!E6:E8)) | F11: =SUM((SharedData!A6:A8,SharedData!E6:E8)) -> 60 | M11: oracle_probe | O11: Uses only deterministic workbook inputs; result must be cached by Excel.
A12: curated:intersection:c008 | B12: Curated behaviour | C12: CURATED | D12: Hand-picked semantic boundary named by the oracle plan | E12: =SUM('SharedData'!A6:INDEX('SharedData'!A:A,10)) | F12: =SUM(SharedData!A6:INDEX(SharedData!A:A,10)) -> 3 | M12: oracle_probe | O12: Uses only deterministic workbook inputs; result must be cached by Excel.
A13: curated:intersection:c009 | B13: Curated behaviour | C13: CURATED | D13: Hand-picked semantic boundary named by the oracle plan | E13: =SUM('SharedData'!6:8) | F13: =SUM(SharedData!6:8) -> 263144.15 | M13: oracle_probe | N13: =IF(ISERROR(F13),"ERROR "&IFERROR(ERROR.TYPE(F13),""),"OK") -> OK | O13: Uses only deterministic workbook inputs; result must be cached by Excel.
A14: curated:intersection:c010 | B14: Curated behaviour | C14: CURATED | D14: Hand-picked semantic boundary named by the oracle plan | E14: =SUM('SharedData'!A:A) | F14: =SUM(SharedData!A:A) -> 157.65 | M14: oracle_probe | O14: Uses only deterministic workbook inputs; result must be cached by Excel.
A15: curated:intersection:c011 | B15: Curated behaviour | C15: CURATED | D15: Hand-picked semantic boundary named by the oracle plan | E15: =COUNT('SharedData'!A:A 'SharedData'!6:8) | F15: =COUNT(SharedData!A:A SharedData!6:8) -> 3 | M15: oracle_probe | O15: Uses only deterministic workbook inputs; result must be cached by Excel.

Sheet Financial
A1: Financial — CellRune Excel Oracle
A2: Blue cells are formulas. Gray rows are catalogued exclusions. Excel must recalculate and save cached values. | R2: Catalog rows | S2: =COUNTA(A5:A65) -> 61
R3: Primary cases | S3: =COUNTA(A5:A65) -> 61
A4: Case ID | B4: Category | C4: Function | D4: Scenario | E4: Formula text | F4: Result / spill zone | M4: Expectation | N4: Sentinel | O4: Note | P4: Dependency signature | R4: Active formulas | S4: =COUNTA(A5:A65)-COUNTIF(M5:M65,"excluded") -> 61
A5: function:accrint | B5: Financial | C5: ACCRINT | D5: Curated deterministic boundary with shared-data and cross-sheet inputs | E5: =ACCRINT(DATE(2024,1,1),DATE(2024,7,1),DATE(2025,1,1),0.05,1000,2) | F5: =ACCRINT(DATE(2024,1,1),DATE(2024,7,1),DATE(2025,1,1),0.05,1000,2) -> 50 | M5: oracle_probe | N5: =IF(ISERROR(F5),"ERROR "&IFERROR(ERROR.TYPE(F5),""),"OK") -> OK | O5: Recalculate in Excel and compare the saved result. | P5: =IFERROR(N(F5),0)+IFERROR(N(Intersection!$F$5),0)+ROW()/100000 -> 50.00005
A6: function:accrintm | B6: Financial | C6: ACCRINTM | D6: Curated deterministic boundary with shared-data and cross-sheet inputs | E6: =ACCRINTM(DATE(2024,1,1),DATE(2025,1,1),0.05,1000,0) | F6: =ACCRINTM(DATE(2024,1,1),DATE(2025,1,1),0.05,1000,0) -> 50 | M6: oracle_probe | O6: Recalculate in Excel and compare the saved result.
A7: function:amordegrc | B7: Financial | C7: AMORDEGRC | D7: Curated deterministic boundary with shared-data and cross-sheet inputs | E7: =AMORDEGRC(10000,DATE(2023,1,1),DATE(2023,12,31),1000,1,0.15,0) | F7: =AMORDEGRC(10000,DATE(2023,1,1),DATE(2023,12,31),1000,1,0.15,0) -> 2344 | M7: oracle_probe | O7: Recalculate in Excel and compare the saved result.
A8: function:amorlinc | B8: Financial | C8: AMORLINC | D8: Curated deterministic boundary with shared-data and cross-sheet inputs | E8: =AMORLINC(10000,DATE(2023,1,1),DATE(2023,12,31),1000,1,0.15,0) | F8: =AMORLINC(10000,DATE(2023,1,1),DATE(2023,12,31),1000,1,0.15,0) -> 1500 | M8: oracle_probe | O8: Recalculate in Excel and compare the saved result.
A9: function:coupdaybs | B9: Financial | C9: COUPDAYBS | D9: Curated deterministic boundary with shared-data and cross-sheet inputs | E9: =COUPDAYBS(DATE(2025,3,15),DATE(2027,1,1),2,0) | F9: =COUPDAYBS(DATE(2025,3,15),DATE(2027,1,1),2,0) -> 74 | M9: oracle_probe | O9: Recalculate in Excel and compare the saved result.
A10: function:coupdays | B10: Financial | C10: COUPDAYS | D10: Curated deterministic boundary with shared-data and cross-sheet inputs | E10: =COUPDAYS(DATE(2025,3,15),DATE(2027,1,1),2,0) | F10: =COUPDAYS(DATE(2025,3,15),DATE(2027,1,1),2,0) -> 180 | M10: oracle_probe | O10: Recalculate in Excel and compare the saved result.
A11: function:coupdaysnc | B11: Financial | C11: COUPDAYSNC | D11: Curated deterministic boundary with shared-data and cross-sheet inputs | E11: =COUPDAYSNC(DATE(2025,3,15),DATE(2027,1,1),2,0) | F11: =COUPDAYSNC(DATE(2025,3,15),DATE(2027,1,1),2,0) -> 106 | M11: oracle_probe | O11: Recalculate in Excel and compare the saved result.
A12: function:coupncd | B12: Financial | C12: COUPNCD | D12: Curated deterministic boundary with shared-data and cross-sheet inputs | E12: =COUPNCD(DATE(2025,3,15),DATE(2027,1,1),2,0) | F12: =COUPNCD(DATE(2025,3,15),DATE(2027,1,1),2,0) -> 45839 | M12: oracle_probe | O12: Recalculate in Excel and compare the saved result.
A13: function:coupnum | B13: Financial | C13: COUPNUM | D13: Curated deterministic boundary with shared-data and cross-sheet inputs | E13: =COUPNUM(DATE(2025,3,15),DATE(2027,1,1),2,0) | F13: =COUPNUM(DATE(2025,3,15),DATE(2027,1,1),2,0) -> 4 | M13: oracle_probe | N13: =IF(ISERROR(F13),"ERROR "&IFERROR(ERROR.TYPE(F13),""),"OK") -> OK | O13: Recalculate in Excel and compare the saved result.
A14: function:couppcd | B14: Financial | C14: COUPPCD | D14: Curated deterministic boundary with shared-data and cross-sheet inputs | E14: =COUPPCD(DATE(2025,3,15),DATE(2027,1,1),2,0) | F14: =COUPPCD(DATE(2025,3,15),DATE(2027,1,1),2,0) -> 45658 | M14: oracle_probe | O14: Recalculate in Excel and compare the saved result.
A15: function:cumipmt | B15: Financial | C15: CUMIPMT | D15: Curated deterministic boundary with shared-data and cross-sheet inputs | E15: =CUMIPMT(0.05/12,60,20000,1,12,0) | F15: =CUMIPMT(0.05/12,60,20000,1,12,0) -> -917.99101 | M15: oracle_probe | O15: Recalculate in Excel and compare the saved result.
A16: function:cumprinc | B16: Financial | C16: CUMPRINC | D16: Curated deterministic boundary with shared-data and cross-sheet inputs | E16: =CUMPRINC(0.05/12,60,20000,1,12,0) | F16: =CUMPRINC(0.05/12,60,20000,1,12,0) -> -3611.1051 | M16: oracle_probe | O16: Recalculate in Excel and compare the saved result.
A17: function:db | B17: Financial | C17: DB | D17: Curated deterministic boundary with shared-data and cross-sheet inputs | E17: =DB(10000,1000,5,2,6) | F17: =DB(10000,1000,5,2,6) -> 3009.195 | M17: oracle_probe | O17: Recalculate in Excel and compare the saved result. | P17: =IFERROR(N(F17),0)+IFERROR(N(Intersection!$F$5),0)+ROW()/100000 -> 3009.1952
A18: function:ddb | B18: Financial | C18: DDB | D18: Curated deterministic boundary with shared-data and cross-sheet inputs | E18: =DDB(10000,1000,5,2,2) | F18: =DDB(10000,1000,5,2,2) -> 2400 | M18: oracle_probe | O18: Recalculate in Excel and compare the saved result.
A19: function:disc | B19: Financial | C19: DISC | D19: Curated deterministic boundary with shared-data and cross-sheet inputs | E19: =DISC(DATE(2025,1,1),DATE(2025,7,1),97,100,0) | F19: =DISC(DATE(2025,1,1),DATE(2025,7,1),97,100,0) -> 0.06 | M19: oracle_probe | O19: Recalculate in Excel and compare the saved result.
A20: function:dollarde | B20: Financial | C20: DOLLARDE | D20: Curated deterministic boundary with shared-data and cross-sheet inputs | E20: =DOLLARDE(1.08,16) | F20: =DOLLARDE(1.08,16) -> 1.5 | M20: oracle_probe | O20: Recalculate in Excel and compare the saved result.
A21: function:dollarfr | B21: Financial | C21: DOLLARFR | D21: Curated deterministic boundary with shared-data and cross-sheet inputs | E21: =DOLLARFR(1.5,16) | F21: =DOLLARFR(1.5,16) -> 1.08 | M21: oracle_probe | N21: =IF(ISERROR(F21),"ERROR "&IFERROR(ERROR.TYPE(F21),""),"OK") -> OK | O21: Recalculate in Excel and compare the saved result.
A22: function:duration | B22: Financial | C22: DURATION | D22: Curated deterministic boundary with shared-data and cross-sheet inputs | E22: =DURATION(DATE(2025,1,1),DATE(2030,1,1),0.05,0.04,2,0) | F22: =DURATION(DATE(2025,1,1),DATE(2030,1,1),0.05,0.04,2,0) -> 4.4989036 | M22: oracle_probe | O22: Recalculate in Excel and compare the saved result.
A23: function:effect | B23: Financial | C23: EFFECT | D23: Curated deterministic boundary with shared-data and cross-sheet inputs | E23: =EFFECT(0.06,12) | F23: =EFFECT(0.06,12) -> 0.061677812 | M23: oracle_probe | O23: Recalculate in Excel and compare the saved result.
A24: function:fv | B24: Financial | C24: FV | D24: Curated deterministic boundary with shared-data and cross-sheet inputs | E24: =FV(0.05/12,60,-250,-5000,0) | F24: =FV(0.05/12,60,-250,-5000,0) -> 23418.314 | M24: oracle_probe | O24: Recalculate in Excel and compare the saved result.
A25: function:fvschedule | B25: Financial | C25: FVSCHEDULE | D25: Curated deterministic boundary with shared-data and cross-sheet inputs | E25: =FVSCHEDULE(1000,{0.02,0.03,0.04,0.05}) | F25: =FVSCHEDULE(1000,{0.02,0.03,0.04,0.05}) -> 1147.2552 | M25: oracle_probe | O25: Recalculate in Excel and compare the saved result.
A26: function:intrate | B26: Financial | C26: INTRATE | D26: Curated deterministic boundary with shared-data and cross-sheet inputs | E26: =INTRATE(DATE(2025,1,1),DATE(2025,7,1),970,1000,0) | F26: =INTRATE(DATE(2025,1,1),DATE(2025,7,1),970,1000,0) -> 0.06185567 | M26: oracle_probe | O26: Recalculate in Excel and compare the saved result.
A27: function:ipmt | B27: Financial | C27: IPMT | D27: Curated deterministic boundary with shared-data and cross-sheet inputs | E27: =IPMT(0.05/12,12,60,20000,0,0) | F27: =IPMT(0.05/12,12,60,20000,0,0) -> -69.569791 | M27: oracle_probe | O27: Recalculate in Excel and compare the saved result.
A28: function:irr | B28: Financial | C28: IRR | D28: Curated deterministic boundary with shared-data and cross-sheet inputs | E28: =IRR('SharedData'!$L$6:$L$15,0.1) | F28: =IRR(SharedData!$L$6:$L$15,0.1) -> 0.21172444 | M28: oracle_probe | O28: Recalculate in Excel and compare the saved result.
A29: function:ispmt | B29: Financial | C29: ISPMT | D29: Curated deterministic boundary with shared-data and cross-sheet inputs | E29: =ISPMT(0.05/12,12,60,20000) | F29: =ISPMT(0.05/12,12,60,20000) -> -66.666667 | M29: oracle_probe | N29: =IF(ISERROR(F29),"ERROR "&IFERROR(ERROR.TYPE(F29),""),"OK") -> OK | O29: Recalculate in Excel and compare the saved result. | P29: =IFERROR(N(F29),0)+IFERROR(N(Intersection!$F$17),0)+ROW()/100000 -> -66.666377
A30: function:mduration | B30: Financial | C30: MDURATION | D30: Curated deterministic boundary with shared-data and cross-sheet inputs | E30: =MDURATION(DATE(2025,1,1),DATE(2030,1,1),0.05,0.04,2,0) | F30: =MDURATION(DATE(2025,1,1),DATE(2030,1,1),0.05,0.04,2,0) -> 4.4106898 | M30: oracle_probe | O30: Recalculate in Excel and compare the saved result.
A31: function:mirr | B31: Financial | C31: MIRR | D31: Curated deterministic boundary with shared-data and cross-sheet inputs | E31: =MIRR('SharedData'!$L$6:$L$15,0.08,0.1) | F31: =MIRR(SharedData!$L$6:$L$15,0.08,0.1) -> 0.15360335 | M31: oracle_probe | O31: Recalculate in Excel and compare the saved result.
A32: function:nominal | B32: Financial | C32: NOMINAL | D32: Curated deterministic boundary with shared-data and cross-sheet inputs | E32: =NOMINAL(0.0617,12) | F32: =NOMINAL(0.0617,12) -> 0.060021003 | M32: oracle_probe | O32: Recalculate in Excel and compare the saved result.
A33: function:nper | B33: Financial | C33: NPER | D33: Curated deterministic boundary with shared-data and cross-sheet inputs | E33: =NPER(0.05/12,-250,5000,0,0) | F33: =NPER(0.05/12,-250,5000,0,0) -> 20.926206 | M33: oracle_probe | O33: Recalculate in Excel and compare the saved result.
A34: function:npv | B34: Financial | C34: NPV | D34: Curated deterministic boundary with shared-data and cross-sheet inputs | E34: =NPV(0.1,'SharedData'!$L$7:$L$15)+'SharedData'!$L$6 | F34: =NPV(0.1,SharedData!$L$7:$L$15)+SharedData!$L$6 -> 553.63778 | M34: oracle_probe | O34: Recalculate in Excel and compare the saved result.
A35: function:oddfprice | B35: Financial | C35: ODDFPRICE | D35: Function-catalog probe with a repaired call signature | E35: =ODDFPRICE(DATE(2025,2,1),DATE(2030,3,1),DATE(2024,11,15),DATE(2025,3,1),0.05,0.06,100,2,0) | F35: =ODDFPRICE(DATE(2025,2,1),DATE(2030,3,1),DATE(2024,11,15),DATE(2025,3,1),0.05,0.06,100,2,0) -> 95.673855 | M35: oracle_probe | O35: Recalculate in Excel and compare the saved result.
A36: function:oddfyield | B36: Financial | C36: ODDFYIELD | D36: Function-catalog probe with a repaired call signature | E36: =ODDFYIELD(DATE(2025,2,1),DATE(2030,3,1),DATE(2024,11,15),DATE(2025,3,1),0.05,95,100,2,0) | F36: =ODDFYIELD(DATE(2025,2,1),DATE(2030,3,1),DATE(2024,11,15),DATE(2025,3,1),0.05,95,100,2,0) -> 0.061605746 | M36: oracle_probe | O36: Recalculate in Excel and compare the saved result.
A37: function:oddlprice | B37: Financial | C37: ODDLPRICE | D37: Function-catalog probe with a repaired call signature | E37: =ODDLPRICE(DATE(2025,2,1),DATE(2025,6,15),DATE(2024,10,15),0.05,0.06,100,2,0) | F37: =ODDLPRICE(DATE(2025,2,1),DATE(2025,6,15),DATE(2024,10,15),0.05,0.06,100,2,0) -> 99.603748 | M37: oracle_probe | N37: =IF(ISERROR(F37),"ERROR "&IFERROR(ERROR.TYPE(F37),""),"OK") -> OK | O37: Recalculate in Excel and compare the saved result.
